Workbook
Name DOCUMENTOS_DEL_CONVENIO: #REF!
Name DOCUMENTOS_DEL_CONVENIO: #REF!
Name DURACION_PRORROGA: #REF!
Name DURACION_PRORROGA: #REF!
Name FECHA_DE_FIN: #REF!
Name FECHA_DE_FIN: #REF!
Name FECHA_DE_INICIO: #REF!
Name FECHA_DE_INICIO: #REF!
Name FIN_PRORROGA: #REF!
Name FIN_PRORROGA: #REF!
Name INICIO_PRORROGA_1: #REF!
Name INICIO_PRORROGA_1: #REF!
Name INICIO_PRORROGA_2: #REF!
Name INICIO_PRORROGA_2: #REF!
Name PropuestasInv: Propuestas!$A$1:$AJ$162
Name SegmentaciónDeDatos_AÑO: #REF!
Name SegmentaciónDeDatos_ENTIDAD: #REF!
Name SegmentaciónDeDatos_ESTADO: #REF!
Name SegmentaciónDeDatos_ROL_UDFJC: #REF!
Name SegmentaciónDeDatos_TIPO: #REF!
Name UBICACIÓN: #REF!
Name UBICACIÓN: #REF!

Sheet Hoja3
A3: Etiquetas de fila
A4: Avalada
A5: No Avalada
A6: No continuo el trámite
A7: Sin aval del Comité de Investigaciones
A8: Contrato firmado
A9: Desistio
A10: Seleccionada
A11: En tramite
A12: Total general

Sheet Propuestas
A1: AÑO | B1: TIPO | C1: ESTADO | D1: No. CONVOCATORIA | E1: NOMBRE CONVOCATORIA | F1: ENTIDAD | G1: ROL UDFJC | H1: ALIADO | I1: PROGRAMA | J1: MESES | K1: GRUPOS DE INVESTIGACIÓN | L1: VALOR PROYECTO | M1: RECURSOS EN EFECTIVO FINANCIADO A UDFJC | N1: VALOR PROYECTO EFECTIVO | O1: VALOR PROYECTO ESPECIE | P1: SOLICITADO A ENTIDAD | Q1: UDFJC EFECTIVO | R1: UDFJC ESPECIE | S1: SOLICITADO ALIADO 1 EFECTIVO | T1: SOLICITADO ALIADO 1 ESPECIE | U1: SOLICITADO ALIADO 2 EFECTIVO | V1: SOLICITADO ALIADO 2 ESPECIE | W1: SOLICITADO ALIADO 3 EFECTIVO | X1: SOLICITADO ALIADO 3 ESPECIE | Y1: SOLICITADO ALIADO 4 EFECTIVO | Z1: SOLICITADO ALIADO 4 ESPECIE | AA1: RESULTADOS ESPERADOS | AB1: PRODUCTOS ESPERADOS | AC1: % Aportes Colciencias | AD1: % Aportes UDFJC | AE1: % Aportes UDFJC Efectivo | AF1: % Aportes UDFJC Especie | AG1: % Aportes Aliado 1 | AH1: % Aportes Aliado 2 | AI1: % Aportes Aliado 3 | AJ1: % Aportes Aliado 4
A2: 2021 | B2: Propuesta de Investigación Alianza Convenio | C2: Contrato firmado | D2: N/A | E2: Presentación propuesta al Proyecto de Inversión 1763 “Un nuevo contrato para mujeres cuidadoras en Fontibón”, 1782 "Un nuevo contrato para la participación ciudadana en Fontibón" y 1758 "Un nuevo contrato para la Cultura en Fontibón" | F2: Alcaldía de Fontibón | G2: Ejecutor | H2: Alcaldía de Fontibón | I2: N/A | J2: 6 | K2: UDFJC: - Vivencias | L2: =+SUM(P2:Z2) -> 440000000 | M2: 320000000 | N2: =+P2+Q2+S2+U2+W2+Y2 -> 384000000 | O2: =+R2+T2+V2+X2+Z2 -> 56000000 | P2: 320000000 | Q2: 64000000 | R2: 56000000 | S2: 0 | T2: 0 | U2: 0 | V2: 0 | W2: 0 | X2: 0 | Y2: 0 | Z2: 0 | AA2: TALLERES: 1. ¿Cómo renovar el sentido de la participación social comunitaria en torno a los conceptos de lo común y la comunidad? 2. La cuestión de los derechos humanos, económicos sociales y culturales en la construcción de territorios de la participación 3. Participación, convivencia y noviolencia 4. Gestión cultural y gestión política 5. Formas económicas en la gestión cultural 6. Tejiendo desarrollo 7. ¿Como pasar del sufrimiento y la enfermedad a la salud y la felicidad, a través del autocuidado? 8. Autocuidado y Desarrollo personal 9. Cuidado personal y autoconocimiento 10. El auto cuidado y el cuidado de otr@s: Una propuesta de plenitud 11. El auto cuidado y la sanación: Una mirada integral cuerpo, mente y espiritualidad. | AB2: - Documento para ser publicado que enfatiza en elementos de orden político, ético, existencial, estético de los diferentes componentes que integran el convenio, abordando los componentes de cuidado, participación y cultura - Se deberá diseñar, elaborar y entregar una cartilla por cada uno de los componentes del proyecto; la descripción técnica tendrá un formato abierto de 22x30 cm y cerrada de 22 X15 cm, con terminado caballete de 15 hojas tiro y retiro, impreso por las dos caras en dos tintas, con portada y contraportada en tres colores - Se creará un artículo académico para difundir en revista con ISBN, por cada uno de los componentes trabajados en el proceso de investigación-formación - Se desplegará un proceso de difusión y comunicación, a través del espacio radial, Voces y Devenires, el Doctorado en Estudios Sociales cuenta con un programa propio “Rizoma” en el cual se estarán transmitiendo noticias del proyecto “Fontibón como espacio cultural, democrático y del cuidado”, además de entrevistas a participantes del proceso investigativo-formativo. - El documento deberá contener los testimonios e insumos testimoniales recogidos a lo largo del proceso de investigación formación - Desarrollo de un proceso de formación orientado a hombres y mujeres de la localidad de Fontibón. Se busca la profundización en la configuración de imaginarios, prácticas y acciones sobre el cuidado, cultura y participación, estableciendo un proceso reflexivo entre las dinámicas institucionales y las vivencias de la ciudadanía de Cuidado y en la interacción cuidado-autocuidado en diversos contextos - Con el apoyo de un equipo de profesionales se trabajará con 30 cuidadores/as que estén participando en el proceso formativo e investigativo. Se impulsa una reflexión y un trabajo teórico y práctico que involucre una concepción crítica de Cuidado y Autocuidado que transite más allá de los sesgos de género o sexo y que muestre sus claras implicaciones éticas, políticas y existenciales. - Desarrollo de cinco tipos de talleres dirigidos a hombres y mujeres que asisten al proceso formativo/investigativo. Estos talleres que enfatizan en aspectos vivenciales, existenciales, éticos y políticos, configuran aspectos que deben ser centrales en un cuidador/a. Son procesos de corte afectivo que le apuntan a la desubjetivación y, además, a formas mutantes que permitan tránsitos más allá de significados y representaciones que circulan sobre el Cuidado en un plano de organización. - Cartografías sociales | AC2: =+IFERROR(P2/L2,0%) -> 0.72727273 | AD2: =+IFERROR((Q2+R2)/L2,0%) -> 0.27272727 | AE2: =IFERROR(Q2/(Q2+R2),0%) -> 0.53333333 | AF2: =IFERROR(R2/(Q2+R2),0%) -> 0.46666667 | AG2: =+IFERROR((S2+T2)/L2,0%) -> 0 | AH2: =+IFERROR((U2+V2)/L2,0%) -> 0 | AI2: =+IFERROR((W2+X2)/L2,0%) -> 0 | AJ2: =+IFERROR((Y2+Z2)/L2,0%) -> 0
A3: 2018 | B3: Propuesta de Investigación Convocatoria | C3: No Avalada | D3: 802 | E3: N/A | F3: MinCiencias | G3: Co-ejecutor | H3: 1- Universidad Minuto de Dios 2- Corporación Centauro Bacatá Alcaldía de Choachí - Alcaldía de Fómeque | I3: N/A | J3: 18 | K3: N/A | L3: =+SUM(P3:Z3) -> 547842614 | M3: 0 | N3: =+P3+Q3+S3+U3+W3+Y3 -> 442541614 | O3: =+R3+T3+V3+X3+Z3 -> 105301000 | P3: 349991614 | Q3: 52650000 | R3: 24301000 | S3: 39900000 | T3: 81000000 | U3: 0 | V3: 0 | W3: 0 | X3: 0 | Y3: 0 | Z3: 0 | AA3: * Participación ciudadana en productos CTel * Alianza con el municipio para promover la apropiación social del conocimiento por parte de la población. * Promover la creación de dos (2) comités de vigilancia, cuidado y recuperación de los acuíferos existentes en el área de influencia del estudio * Formación de 4 estudiantes de pregrado * Formación de 2 estudiantes de maestría | AB3: * Mapa geomorfológico que identifique los acuíferos presentes en el área de estudio y su interrelación. * Cartilla de cuidado y uso de los acuíferos * Un libro * Un artículo | AC3: =+IFERROR(P3/L3,0%) -> 0.63885431 | AD3: =+IFERROR((Q3+R3)/L3,0%) -> 0.14046187 | AE3: =IFERROR(Q3/(Q3+R3),0%) -> 0.68420163 | AF3: =IFERROR(R3/(Q3+R3),0%) -> 0.31579837 | AG3: =+IFERROR((S3+T3)/L3,0%) -> 0.22068382 | AH3: =+IFERROR((U3+V3)/L3,0%) -> 0 | AI3: =+IFERROR((W3+X3)/L3,0%) -> 0 | AJ3: =+IFERROR((Y3+Z3)/L3,0%) -> 0
A4: 2018 | B4: Propuesta de Investigación Convocatoria | C4: No Avalada | D4: 802 | E4: N/A | F4: MinCiencias | G4: Co-ejecutor | H4: 1- Universidad Minuto de Dios 2- Corporación Centauro Bacatá Beneficiarios: I.E.D IGNACIO PESCADOR DE CHOACHI I.E.D MONSEÑOR AGUSTIN GUTIERREZ DE FOMEQUE | I4: N/A | J4: 18 | K4: N/A | L4: =+SUM(P4:Z4) -> 507842614 | M4: 0 | N4: =+P4+Q4+S4+U4+W4+Y4 -> 402641614 | O4: =+R4+T4+V4+X4+Z4 -> 105201000 | P4: 349991614 | Q4: 52650000 | R4: 8101000 | S4: 0 | T4: 97100000 | U4: 0 | V4: 0 | W4: 0 | X4: 0 | Y4: 0 | Z4: 0 | AA4: * Participación ciudadana en productos Ctel * Alianza con centro dedicado a la apropiación social del conocimiento * Formación de 4 estudiantes de pregrado * Formación de dos estudiantes de maestría | AB4: * Mapa de cobertura vegetal * Un libro * Un articulo * Guía de cuidado, uso de especies vegetales | AC4: =+IFERROR(P4/L4,0%) -> 0.68917339 | AD4: =+IFERROR((Q4+R4)/L4,0%) -> 0.11962564 | AE4: =IFERROR(Q4/(Q4+R4),0%) -> 0.8666524 | AF4: =IFERROR(R4/(Q4+R4),0%) -> 0.1333476 | AG4: =+IFERROR((S4+T4)/L4,0%) -> 0.19120097 | AH4: =+IFERROR((U4+V4)/L4,0%) -> 0 | AI4: =+IFERROR((W4+X4)/L4,0%) -> 0 | AJ4: =+IFERROR((Y4+Z4)/L4,0%) -> 0
A5: 2018 | B5: Propuesta de Investigación Convocatoria | C5: No Avalada | D5: 806 | E5: N/A | F5: MinCiencias | G5: Ejecutor | H5: Programa ECOSNORD Francia | I5: N/A | J5: 36 | K5: N/A | L5: =+SUM(P5:Z5) -> 78000000 | M5: 0 | N5: =+P5+Q5+S5+U5+W5+Y5 -> 0 | O5: =+R5+T5+V5+X5+Z5 -> 78000000 | P5: 0 | Q5: 0 | R5: 78000000 | S5: 0 | T5: 0 | U5: 0 | V5: 0 | W5: 0 | X5: 0 | Y5: 0 | Z5: 0 | AA5: * Proyecto de documental UVED Parque Chingaza (equivalente del proyecto UVED Reerva de la Biosfera Mapimí) * Publicaciones (VIA revista sobre el ecosistema, Geocarrefour, …) * Coordinación de un Simposio en el 9º Congreso Internacional del Consejo Europeo de Investigaciones Sociales de América Latina (CEISAL) Alvaro Gutiérrez/Teresa Alarcón 2019 * Coordinación de un número de la revista ORDA 2021 | AB5: 0 | AC5: =+IFERROR(P5/L5,0%) -> 0 | AD5: =+IFERROR((Q5+R5)/L5,0%) -> 1 | AE5: =IFERROR(Q5/(Q5+R5),0%) -> 0 | AF5: =IFERROR(R5/(Q5+R5),0%) -> 1 | AG5: =+IFERROR((S5+T5)/L5,0%) -> 0 | AH5: =+IFERROR((U5+V5)/L5,0%) -> 0 | AI5: =+IFERROR((W5+X5)/L5,0%) -> 0 | AJ5: =+IFERROR((Y5+Z5)/L5,0%) -> 0
A6: 2018 | B6: Propuesta de Investigación Convocatoria | C6: No Avalada | D6: 806 | E6: N/A | F6: MinCiencias | G6: Ejecutor | H6: Programa ECOSNORD Alemania | I6: N/A | J6: 24 | K6: N/A | L6: =+SUM(P6:Z6) -> 108915069 | M6: 0 | N6: =+P6+Q6+S6+U6+W6+Y6 -> 69657534 | O6: =+R6+T6+V6+X6+Z6 -> 39257535 | P6: 69657534 | Q6: 0 | R6: 39257535 | S6: 0 | T6: 0 | U6: 0 | V6: 0 | W6: 0 | X6: 0 | Y6: 0 | Z6: 0 | AA6: 0 | AB6: 0 | AC6: =+IFERROR(P6/L6,0%) -> 0.63955828 | AD6: =+IFERROR((Q6+R6)/L6,0%) -> 0.36044172 | AE6: =IFERROR(Q6/(Q6+R6),0%) -> 0 | AF6: =IFERROR(R6/(Q6+R6),0%) -> 1 | AG6: =+IFERROR((S6+T6)/L6,0%) -> 0 | AH6: =+IFERROR((U6+V6)/L6,0%) -> 0 | AI6: =+IFERROR((W6+X6)/L6,0%) -> 0 | AJ6: =+IFERROR((Y6+Z6)/L6,0%) -> 0
A7: 2018 | B7: Propuesta de Investigación Convocatoria | C7: No Avalada | D7: 807 | E7: N/A | F7: MinCiencias | G7: Ejecutor | H7: HOME ROBOTIK SAS | I7: N/A | J7: 24 | K7: N/A | L7: =+SUM(P7:Z7) -> 774423518 | M7: 0 | N7: =+P7+Q7+S7+U7+W7+Y7 -> 599623518 | O7: =+R7+T7+V7+X7+Z7 -> 174800000 | P7: 528252518 | Q7: 51371000 | R7: 124400000 | S7: 20000000 | T7: 50400000 | U7: 0 | V7: 0 | W7: 0 | X7: 0 | Y7: 0 | Z7: 0 | AA7: * PROTOTIPO FUNCIONAL DE UN SISTEMA SUMERGIBLE DE _VISIÓN ARTIFICIAL PARA LA MEDICIÓN Y PROCESAMÍENTO BIOMECÁNICO DEL TREN INFERIOR HUMANO DURANTE LA REHABILITACIÓN EN PISCINA PARA ENFERMEDADES NEUROMUSCULARES * Sistema de Visión Artificial Sumergible * Sistema de Seguimiento Automático del Objetivo * Sistema de Procesamiento y Visualización de Datos. * Sistema de Telemedicina | AB7: * Artículo de investigación * Libro resultado de investigación * Ejemplar del libro resultado de la investigación o carta de aceptación de publicación del libro expedida por el comité editorial * Producto tecnológico patentado o en proceso de solicitud de patente * Prototipo de sistema * Registro de Software | AC7: =+IFERROR(P7/L7,0%) -> 0.68212355 | AD7: =+IFERROR((Q7+R7)/L7,0%) -> 0.22697012 | AE7: =IFERROR(Q7/(Q7+R7),0%) -> 0.29226095 | AF7: =IFERROR(R7/(Q7+R7),0%) -> 0.70773905 | AG7: =+IFERROR((S7+T7)/L7,0%) -> 0.09090633 | AH7: =+IFERROR((U7+V7)/L7,0%) -> 0 | AI7: =+IFERROR((W7+X7)/L7,0%) -> 0 | AJ7: =+IFERROR((Y7+Z7)/L7,0%) -> 0
A8: 2018 | B8: Propuesta de Investigación Convocatoria | C8: No Avalada | D8: 808 | E8: N/A | F8: MinCiencias | G8: Ejecutor | H8: N/A | I8: N/A | J8: 30 | K8: N/A | L8: =+SUM(P8:Z8) -> 439445398 | M8: 0 | N8: =+P8+Q8+S8+U8+W8+Y8 -> 259271998 | O8: =+R8+T8+V8+X8+Z8 -> 180173400 | P8: 241989411 | Q8: 17282587 | R8: 180173400 | S8: 0 | T8: 0 | U8: 0 | V8: 0 | W8: 0 | X8: 0 | Y8: 0 | Z8: 0 | AA8: * Formación culminada del estudiante de doctorado en el marco del proyecto. * Vinculación del joven investigador al proyecto * Formación culminada del estudiante de pregrado al proyecto * Tesis de maestría en ejecución, enmarcada en el proyecto financiado * Organización de eventos especializados * Presentación de los resultados ante las autoridades competentes * Documento sobre la patente y/o Registro de propiedad intelectual | AB8: * Dos (2) artículos publicados en revistas A de PUBLINDEX (Q1 o Q2). * Dos (2) artículos publicados en revistas B de PUBLINDEX (Q3) * Libro - documento final tesis Doctoral | AC8: =+IFERROR(P8/L8,0%) -> 0.55067003 | AD8: =+IFERROR((Q8+R8)/L8,0%) -> 0.44932997 | AE8: =IFERROR(Q8/(Q8+R8),0%) -> 0.087526275 | AF8: =IFERROR(R8/(Q8+R8),0%) -> 0.91247373 | AG8: =+IFERROR((S8+T8)/L8,0%) -> 0 | AH8: =+IFERROR((U8+V8)/L8,0%) -> 0 | AI8: =+IFERROR((W8+X8)/L8,0%) -> 0 | AJ8: =+IFERROR((Y8+Z8)/L8,0%) -> 0
A9: 2018 | B9: Propuesta de Investigación Convocatoria | C9: No Avalada | D9: 804 | E9: N/A | F9: MinCiencias | G9: Co-ejecutor | H9: 1- Konrad Lorenz - Ejecutor 2- Universidad Católica de Oriente - Coejecutor 3- Log On Colombia | I9: N/A | J9: 18 | K9: N/A | L9: =+SUM(P9:Z9) -> 8.6255883e+08 | M9: 0 | N9: =+P9+Q9+S9+U9+W9+Y9 -> 536553394 | O9: =+R9+T9+V9+X9+Z9 -> 3.2600543e+08 | P9: 536553394 | Q9: 0 | R9: 131800000 | S9: 0 | T9: 1.7440543e+08 | U9: 0 | V9: 0 | W9: 0 | X9: 19800000 | Y9: 0 | Z9: 0 | AA9: * Perfil sociodemográfico y psicográfico de los estudiantes de educación virtual de dos zonas de Antioquia, identificando su perfil tecnológico, su historia de interacción con entornos virtuales y sus competencias de autorregulación * Evidencia, a partir de las actividades de investigación y la metodología descrita, de los componentes pedagógicos necesarios para la implementación del programa. | AB9: * Dos artículos sometidos a revistas de impacto (Q1-Q2). * Informe final sobre el diseño, construcción y validación del programa de intervención pedagógica para la prevención de la deserción y aumento del éxito estudiantil. * Mundo virtual 3D para la implementación y uso del programa de intervención pedagógica para la prevención de la deserción y aumento del éxito estudiantil. * Informe final sobre las recomendaciones para el uso del programa de intervención pedagógica para la prevención de la deserción y aumento del éxito estudiantil. * Participación en dos eventos científicos. | AC9: =+IFERROR(P9/L9,0%) -> 0.62204846 | AD9: =+IFERROR((Q9+R9)/L9,0%) -> 0.15280117 | AE9: =IFERROR(Q9/(Q9+R9),0%) -> 0 | AF9: =IFERROR(R9/(Q9+R9),0%) -> 1 | AG9: =+IFERROR((S9+T9)/L9,0%) -> 0.20219541 | AH9: =+IFERROR((U9+V9)/L9,0%) -> 0 | AI9: =+IFERROR((W9+X9)/L9,0%) -> 0.022954956 | AJ9: =+IFERROR((Y9+Z9)/L9,0%) -> 0
A10: 2018 | B10: Propuesta de Investigación Convocatoria | C10: No Avalada | D10: 807 | E10: N/A | F10: MinCiencias | G10: Ejecutor | H10: 1- Empresa ING - Elkin Yamith Gualteros Vanegas 2- Hospital Central de la Policia Nacional HOCEN | I10: N/A | J10: 34 | K10: N/A | L10: =+SUM(P10:Z10) -> 355285227 | M10: 0 | N10: =+P10+Q10+S10+U10+W10+Y10 -> 288285227 | O10: =+R10+T10+V10+X10+Z10 -> 67000000 | P10: 229335227 | Q10: 23000000 | R10: 42000000 | S10: 26200000 | T10: 0 | U10: 0 | V10: 0 | W10: 9750000 | X10: 25000000 | Y10: 0 | Z10: 0 | AA10: * Tener un protocolo indicador de los pacientes con neumon a adquirida en comunidad que pueden acceder en el sistema hospitalizaci on domiciliaria. * Dispositivos biom etricos basados en el IoT que obtengan constantemente los signos vitales del paciente. * Un software que se encargue de registrar y administrar la evoluci on del paciente teniendo en cuenta la monitorizaci on constante de los dispositivos conectados a la red y que el centro asistencial pueda observar los datos recogidos. * Documento que gestione la parte administrativa de los instrumentos y sirva de guía para respuesta inmediata en caso de emergencia u otra eventualidad. * Evidencia de una prueba piloto en el que se especi que la evoluci on de los pacientes, los gastos y la viabilidad del proyecto a una escala mayor. | AB10: PONENCIAS: Participacion congresos internacionales para la divulgaci on de resultados. PONENCIAS: Participacion en congresos nacionales para la divulgaci on de resultados. ARTICULO ORIGINAL EN REVISTA INDEXADA:Articulo original publicado en cualquier revista clasi cadas como A1, A2, B, C. PRODUCTOS TECNOL OGICOS CERTIFICADOS O VALIDADOS: Plataforma virtual (software) de conexi on paciente-centro asistencial. PRODUCTOS TECNOL OGICOS CERTIFICADOS O VALIDADOS : Validaci on de los dispositivos de monitorizaci on de signos vitales a pacientes con neumonia adquirida en comunidad. CARTILLA: Elaboraci on y divulgaci on de una cartilla donde se evidencie la propuesta de un nuevo modelo de hospitalizaci on domiciliaria con sus respectivos protocolos y normas. REALIZACI ON DE CURSOS DE CAPACITACI ON, SEMINARIOS Y TALLERES : Realizar una capacitaci on al personal de la salud de acuerdo a la investigaci on y procedimientos de nuestro proyecto. PRESENTACI ON DE LOS RESULTADOS A LAS AUTORIDADES LOCALES, NACIONALES Y SECTORIALES: Presentar resultados del estudio acerca de la viabilidad de un modelo de | AC10: =+IFERROR(P10/L10,0%) -> 0.6454961 | AD10: =+IFERROR((Q10+R10)/L10,0%) -> 0.1829516 | AE10: =IFERROR(Q10/(Q10+R10),0%) -> 0.35384615 | AF10: =IFERROR(R10/(Q10+R10),0%) -> 0.64615385 | AG10: =+IFERROR((S10+T10)/L10,0%) -> 0.073743567 | AH10: =+IFERROR((U10+V10)/L10,0%) -> 0 | AI10: =+IFERROR((W10+X10)/L10,0%) -> 0.097808739 | AJ10: =+IFERROR((Y10+Z10)/L10,0%) -> 0
A11: 2018 | B11: Propuesta de Investigación Convocatoria | C11: No Avalada | D11: 808 | E11: N/A | F11: MinCiencias | G11: Ejecutor | H11: Grupos de investigación UDFJC: 1- GCEM 2- LIFAE 3- GITUD | I11: N/A | J11: 24 | K11: N/A | L11: =+SUM(P11:Z11) -> 3.8771405e+08 | M11: 0 | N11: =+P11+Q11+S11+U11+W11+Y11 -> 239984850 | O11: =+R11+T11+V11+X11+Z11 -> 1.477292e+08 | P11: 239984850 | Q11: 0 | R11: 1.477292e+08 | S11: 0 | T11: 0 | U11: 0 | V11: 0 | W11: 0 | X11: 0 | Y11: 0 | Z11: 0 | AA11: * Profundo conocimiento de las funciones de diseño, construcción e implementación de sistemas de registro inteligentes, al igual que un procedimiento técnico ara la selección del hardware y software requerido en el proyecto * Validación y mejora de los sistemas de apantallamiento y aislamiento gracias a las pruebas en laboratorio, simulación a través de herramientas computacionales. Identificación de los sistemas de conexión y la metodología de montaje óptima. * El estudio preliminar de mercado permitirá realizar la búsqueda de principales actores de mercado, fortalezas, debilidades y diferencias con los competidores. Se realizará un análisis de la distribución geográfica, temporal y tipología del mercado. Por último, se realizará la búsqueda de competidores * Se conseguirá identificar los procesos y requisitos necesarios para realizar la protección intelectual del conocimiento generado | AB11: * Formación culminada del estudiante de maestría (2) * Participación en eventos especializados, presentando los resultados de la investigación (2) * Se dictará un curso de diseño de PCBs de veinte (20) horas * Artículos de investigación A2 (2) * SOFTWARE: Código fuente o manual de instalación. Registro de software ante entidades competentes * PROTOTIPO: Planos de diseño o sus fotografías o demás soportes de existencia | AC11: =+IFERROR(P11/L11,0%) -> 0.61897383 | AD11: =+IFERROR((Q11+R11)/L11,0%) -> 0.38102617 | AE11: =IFERROR(Q11/(Q11+R11),0%) -> 0 | AF11: =IFERROR(R11/(Q11+R11),0%) -> 1 | AG11: =+IFERROR((S11+T11)/L11,0%) -> 0 | AH11: =+IFERROR((U11+V11)/L11,0%) -> 0 | AI11: =+IFERROR((W11+X11)/L11,0%) -> 0 | AJ11: =+IFERROR((Y11+Z11)/L11,0%) -> 0
A12: 2018 | B12: Propuesta de Investigación Convocatoria | C12: No Avalada | D12: 807 | E12: N/A | F12: MinCiencias | G12: Ejecutor | H12: 1- Grupo GITEM++ 2- Laboratorio de Investigación en Fuentes Alternativas de Energía (LIFAE) | I12: N/A | J12: 36 | K12: N/A | L12: =+SUM(P12:Z12) -> 386200000 | M12: 0 | N12: =+P12+Q12+S12+U12+W12+Y12 -> 285400000 | O12: =+R12+T12+V12+X12+Z12 -> 100800000 | P12: 257400000 | Q12: 28000000 | R12: 100800000 | S12: 0 | T12: 0 | U12: 0 | V12: 0 | W12: 0 | X12: 0 | Y12: 0 | Z12: 0 | AA12: 1- Criterios de diagnóstico que propendan por disminución de la probabilidad de falsos negativos. 2- Nueva técnica matemática que permita extraer la información relevante para el diagnóstico desde la imagen medica de la retina. 3- Software que permita modelar un vaso sanguíneo desde el modelo matemático producto del segundo objetivo y a su vez permita verificar dicho modelo matemático como herramienta de diagnóstico de la retinopatía diabética. 4- Modelo matemático del comportamiento dinámico de la irrigación sanguínea en cercanías de la retina, que permita determinar el estadio patológico actual de la retinopatía diabética y que permita predecir la evolución de la patología en un paciente particular. 5- Software que permita verificar el modelo obtenido. | AB12: 1- Formación de estudiante de doctorado: Formación culminada de estudiante de doctorado en el marco del proyecto. 2- Ponencias: Se realizará dos ponencias de presentación de resultados de la investigación en sendos eventos académicos internacionales. 3- Participación en eventos científicos: Se participará en por lo menos un evento científicos internacional del área de la salud ocular, donde se presentarán resultados de la investigación. 4- Articulo original en revista indexada: Se presentará artículo en categoría A2 y articulo en categoría Al. 5- Capítulo en libro resultado de investigación: Se entregará capítulo de libro o borrador sometido a evaluación. | AC12: =+IFERROR(P12/L12,0%) -> 0.66649404 | AD12: =+IFERROR((Q12+R12)/L12,0%) -> 0.33350596 | AE12: =IFERROR(Q12/(Q12+R12),0%) -> 0.2173913 | AF12: =IFERROR(R12/(Q12+R12),0%) -> 0.7826087 | AG12: =+IFERROR((S12+T12)/L12,0%) -> 0 | AH12: =+IFERROR((U12+V12)/L12,0%) -> 0 | AI12: =+IFERROR((W12+X12)/L12,0%) -> 0 | AJ12: =+IFERROR((Y12+Z12)/L12,0%) -> 0
A13: 2018 | B13: Propuesta de Investigación Convocatoria | C13: No Avalada | D13: 807 | E13: N/A | F13: MinCiencias | G13: Ejecutor | H13: 1- Universidad del Valle 2- Hospital Universitario del Valle Evaristo García ESE 3- Universidad de la Rioja | I13: N/A | J13: 36 | K13: N/A | L13: =+SUM(P13:Z13) -> 1694823566 | M13: 0 | N13: =+P13+Q13+S13+U13+W13+Y13 -> 555364566 | O13: =+R13+T13+V13+X13+Z13 -> 1139459000 | P13: 539364566 | Q13: 0 | R13: 494102000 | S13: 0 | T13: 339597000 | U13: 0 | V13: 193440000 | W13: 16000000 | X13: 112320000 | Y13: 0 | Z13: 0 | AA13: 1. Vinculación 2 Jóvenes Investigadores (UDISTRITAL Y UNIVALLE) 2.Vinculación Estudiante de Maestría 3. Formación Culminada Estudiante de Pregrado 4. Participación en eventos científicos, presentando los resultados de la investigación CUATRO (4) 5. Dos cursos de capacitación, seminarios o talleres realizados. 6. Artículo Original en Revista Indexada A1 7. Artículo Original en Revista Indexada A2 8. DOS Artículos Original en Revista Indexada B 9.Registro de Software 10. Empresas de base tecnológica (spin-off), | AB13: 1. Contrato de vinculación del joven investigador e informe de las actividades desarrolladas en el marco del proyecto. 2.Documento que certifique que el trabajo de grado se realiza en el marco del proyecto, emitido por la autoridad en investigación de la institución educativa e informe de actividades realizadas. 3. Documento que certifique el trabajo de grado realizado por el estudiante de pregrado en el marco del proyecto y el acta de grado. 4. Producto: Certificado como de participación como ponente y soporte del trabajo presentado (memorias, programa de los eventos). 5. Programa del curso, capacitación, seminario o taller; intensidad horaria, duración y lista de asistencia. 6. Copia del artículo original aceptado en revista categorizada o la carta de aceptación del artículo. 7. Copia del artículo original aceptado en revista categorizada o la carta de aceptación del artículo. 8.Copia del artículo original aceptado en revista categorizada o la carta de aceptación del artículo. 9.Certificación de registro aprobado por la institución otorgante. 10. Registro del producto o de la empresa ante la entidad competente, certificación institucional firmada por el representante legal que declare la implementación de la innovación en pequeñas, medianas y grandes empresas. | AC13: =+IFERROR(P13/L13,0%) -> 0.31824231 | AD13: =+IFERROR((Q13+R13)/L13,0%) -> 0.29153595 | AE13: =IFERROR(Q13/(Q13+R13),0%) -> 0 | AF13: =IFERROR(R13/(Q13+R13),0%) -> 1 | AG13: =+IFERROR((S13+T13)/L13,0%) -> 0.20037307 | AH13: =+IFERROR((U13+V13)/L13,0%) -> 0.11413577 | AI13: =+IFERROR((W13+X13)/L13,0%) -> 0.075712896 | AJ13: =+IFERROR((Y13+Z13)/L13,0%) -> 0
A14: 2018 | B14: Propuesta de Investigación Convocatoria | C14: No Avalada | D14: 808 | E14: N/A | F14: MinCiencias | G14: Ejecutor | H14: 1- Grupo GIIRA 2- Grupo GITUD | I14: N/A | J14: 36 | K14: N/A | L14: =+SUM(P14:Z14) -> 477567000 | M14: 0 | N14: =+P14+Q14+S14+U14+W14+Y14 -> 241535000 | O14: =+R14+T14+V14+X14+Z14 -> 236032000 | P14: 241535000 | Q14: 0 | R14: 236032000 | S14: 0 | T14: 0 | U14: 0 | V14: 0 | W14: 0 | X14: 0 | Y14: 0 | Z14: 0 | AA14: 1- Modelo conceptual de representación del información espacial y espectral basado en una adecuada captura de datos considerando las propiedades físicas y temporales de la vegetación a evaluar. 2- Modelos digitales de elevación y ortofotomosaicos con un muestreo hiper-temporal para su análisis, 3- Identificación de los índices espectrales con una relación influyente para una estimación cuantitativa en la condición de la vegetación. 4- Metodología adecuada para el procesamiento de la información, que generen índices de calidad y permitan realizar detecciones de cambio en la condición de la vegetación. 5- Documento que contenga los lineamientos metodológicos para la captura, análisis y evaluación de la condición vegetal en sistemas agroecológicos mediante imágenes obtenidas con vehículos aéreos no tripulados. | AB14: 1- Formación de estudiantes de Maestría (2) 2- Vinculación de estudiante de doctorado 3- Ponencias (2): Participación en eventos científicos 4- Seminarios (2) 5- ARTICULO ORIGINAL EN REVISTA INDEXADA tipo top (A1 o A2) 6- ARTICULO ORIGINAL EN REVISTA INDEXADA tipo A (B o C) 7- Libro o borrador de libro sometido a evaluación. | AC14: =+IFERROR(P14/L14,0%) -> 0.5057615 | AD14: =+IFERROR((Q14+R14)/L14,0%) -> 0.4942385 | AE14: =IFERROR(Q14/(Q14+R14),0%) -> 0 | AF14: =IFERROR(R14/(Q14+R14),0%) -> 1 | AG14: =+IFERROR((S14+T14)/L14,0%) -> 0 | AH14: =+IFERROR((U14+V14)/L14,0%) -> 0 | AI14: =+IFERROR((W14+X14)/L14,0%) -> 0 | AJ14: =+IFERROR((Y14+Z14)/L14,0%) -> 0
A15: 2018 | B15: Propuesta de Investigación Convocatoria | C15: No Avalada | D15: 808 | E15: N/A | F15: MinCiencias | G15: Co-ejecutor | H15: 1- TECSOL | I15: N/A | J15: 24 | K15: N/A | L15: =+SUM(P15:Z15) -> 416335317 | M15: 0 | N15: =+P15+Q15+S15+U15+W15+Y15 -> 313585317 | O15: =+R15+T15+V15+X15+Z15 -> 102750000 | P15: 313585317 | Q15: 0 | R15: 60750000 | S15: 0 | T15: 42000000 | U15: 0 | V15: 0 | W15: 0 | X15: 0 | Y15: 0 | Z15: 0 | AA15: 1- Tesis de doctorado 2- Trabajo de grado de pregrado | AB15: 1- Artículo en revista indexada (2) 2- Ponencia en evento científico (2) 3- Informe técnico Final 4- Taller de divulgación con industriales (a los 10 meses de inicio) 5- Taller de socialización con industriales y búsqueda de financiación (a los 22meses de inicio) | AC15: =+IFERROR(P15/L15,0%) -> 0.75320374 | AD15: =+IFERROR((Q15+R15)/L15,0%) -> 0.14591604 | AE15: =IFERROR(Q15/(Q15+R15),0%) -> 0 | AF15: =IFERROR(R15/(Q15+R15),0%) -> 1 | AG15: =+IFERROR((S15+T15)/L15,0%) -> 0.10088022 | AH15: =+IFERROR((U15+V15)/L15,0%) -> 0 | AI15: =+IFERROR((W15+X15)/L15,0%) -> 0 | AJ15: =+IFERROR((Y15+Z15)/L15,0%) -> 0
A16: 2018 | B16: Propuesta de Investigación Convocatoria | C16: No Avalada | D16: 808 | E16: N/A | F16: MinCiencias | G16: Ejecutor | H16: 1- Grupo LIDER 2- Grupo LASER | I16: N/A | J16: 36 | K16: N/A | L16: =+SUM(P16:Z16) -> 376834000 | M16: 0 | N16: =+P16+Q16+S16+U16+W16+Y16 -> 241834000 | O16: =+R16+T16+V16+X16+Z16 -> 135000000 | P16: 241834000 | Q16: 0 | R16: 135000000 | S16: 0 | T16: 0 | U16: 0 | V16: 0 | W16: 0 | X16: 0 | Y16: 0 | Z16: 0 | AA16: 1- Vinculación de un (1) estudiante de doctorado 2- Formación de dos (2) Magister 3- Formación de dos (2) profesionales 4- Dos (2) ponencias internacionales 5- Participación en tres (3) eventos científicos 6- Organización de un (1) evento científico | AB16: 1- Dos (2) artículos categoría A1, A2, B y C. 2- Publicación de un libro o borrador sometido a evaluación | AC16: =+IFERROR(P16/L16,0%) -> 0.64175207 | AD16: =+IFERROR((Q16+R16)/L16,0%) -> 0.35824793 | AE16: =IFERROR(Q16/(Q16+R16),0%) -> 0 | AF16: =IFERROR(R16/(Q16+R16),0%) -> 1 | AG16: =+IFERROR((S16+T16)/L16,0%) -> 0 | AH16: =+IFERROR((U16+V16)/L16,0%) -> 0 | AI16: =+IFERROR((W16+X16)/L16,0%) -> 0 | AJ16: =+IFERROR((Y16+Z16)/L16,0%) -> 0
A17: 2018 | B17: Propuesta de Investigación Alianza Convenio | C17: Contrato firmado | D17: N/A | E17: N/A | F17: Fuerza Aérea Colombiana FAC | G17: Ejecutor | H17: Fuerza Aérea Colombiana FAC | I17: N/A | J17: 17 | K17: N/A | L17: =+SUM(P17:Z17) -> 948000000 | M17: 0 | N17: =+P17+Q17+S17+U17+W17+Y17 -> 0 | O17: =+R17+T17+V17+X17+Z17 -> 948000000 | P17: 0 | Q17: 0 | R17: 298000000 | S17: 0 | T17: 650000000 | U17: 0 | V17: 0 | W17: 0 | X17: 0 | Y17: 0 | Z17: 0 | AA17: Dominio Institucional • Tanto la Universidad como la Fuerza Aérea Colombiana desarrollan su misionalidad generando y difundiendo saberes con vocación hacia el desarrollo sociocultural en defensa de la soberanía e integridad del territorio desde una perspectiva de sostenibilidad ambiental. • Se consolidan procesos de investigación interinstitucionales que fortalecen los ámbitos académicos y tecnológicos en la búsqueda mancomunada del desarrollo social como fin primordial del Estado. • Se afianza el compromiso de la Fuerza Aérea Colombiana en el despliegue de proyectos de protección ambiental que procuran una mayor producción de oxígeno, no sólo para la nación de la que hace parte de su defensa, sino para beneficio global. Dominio lnvestigativo • Fomento del cambio de perspectiva en el abordaje de problemáticas complejas que requieren la articulación de equipos de trabajo multidisciplinarios. • Integración de la óptica civil a los proyectos de defensa de la soberanía e integridad del territorio, a partir de núcleos comunes de trabajo. • Generación de nuevas narrativas de interpretación de la problemática del deterioro ambiental causado por estrategias mineras no planificadas. • Explotación inteligente de bancos de datos del territorio nacional para garantizar el derecho y obligación del Estado y de las personas de proteger las riquezas y naturales de la Nación • Divulgación de resultados y experiencias en eventos nacionales e internacionales. Dominio Tecnológico • Se dota a la nación de una federación de herramientas para el análisis de datos multifuente, multi-formato; con capacidad de ser utilizada en los estudios de afectación ambiental con una perspectiva multimedia!. • Se fomenta la estandarización de datos y procesos (ambiente común de datos) para su visualización multitemporal y multidimensional en entornos Web (4D y SD). • Se propicia el enriquecimiento semántico de la metadata a partir de la definición de una ontología específica que permita la representación del conocimiento del dominio de afectación ambiental de lechos fluviales. • Al estar centrado en la arquitectura, se obtiene el beneficio de establecer un modelo base sobre el cual se integrarán los componentes en un ecosistema orientado a servicios. | AB17: * Generación de conocimiento: Un artículo indexado, Una ponencia, un registro de software. *Nuevos desarrollos tecnológicos: Un modelo y sistema de predicción * Fortalecimiento de la capacidad científica: Formación de Un Magíster, Formación de un Ingeniero * Fortalecimiento de la capacidad institucional: Futuros trabajos en alianza y colaboración, reconocimientos por parte del estado. * Apropiación social del conocimiento: Informes manuales, y transferencia al sector productivo. | AC17: =+IFERROR(P17/L17,0%) -> 0 | AD17: =+IFERROR((Q17+R17)/L17,0%) -> 0.31434599 | AE17: =IFERROR(Q17/(Q17+R17),0%) -> 0 | AF17: =IFERROR(R17/(Q17+R17),0%) -> 1 | AG17: =+IFERROR((S17+T17)/L17,0%) -> 0.68565401 | AH17: =+IFERROR((U17+V17)/L17,0%) -> 0 | AI17: =+IFERROR((W17+X17)/L17,0%) -> 0 | AJ17: =+IFERROR((Y17+Z17)/L17,0%) -> 0
A18: 2018 | B18: Propuesta de Investigación Convocatoria | C18: No Avalada | D18: 816 | E18: N/A | F18: MinCiencias | G18: Co-ejecutor | H18: GIM Ingeniería Eléctrica LTDA | I18: N/A | J18: 12 | K18: N/A | L18: =+SUM(P18:Z18) -> 770564675 | M18: 0 | N18: =+P18+Q18+S18+U18+W18+Y18 -> 599046915 | O18: =+R18+T18+V18+X18+Z18 -> 171517760 | P18: 599046915 | Q18: 0 | R18: 44843496 | S18: 0 | T18: 126674264 | U18: 0 | V18: 0 | W18: 0 | X18: 0 | Y18: 0 | Z18: 0 | AA18: 1- Levantamiento de Requerimientos: Informe con necesidades, Diagrama de Procesos, Documento de análisis de funcionamiento de la línea de producción, Fichas de equipos documentados, Fichas de puestos de trabajo. 2- Diseño global del sistema de seguimiento y los requerimientos monitoreo inteligente: Documento con el levantamiento de los requerimientos, URL con acceso a las funciones de la arquitectura de software 3- Adquisición de equipos software y servicios tecnológicos: Informe con las especificaciones de los requerimientos para el diseño de software, Manual de procesos de adquisiciones 4- Instalación de elementos adquiridos: Documentos con las especificaciones técnicas de los sensores, Informe con los detalles de la implementación y el estado del sistema 5- Evaluación: Tablas de evaluación del nivel de satisfacción de las adquisiciones, Informe técnico con las variables implementadas en la base de datos, Interfaz gráfica del sistema. | AB18: Sistema de seguimiento y monitoreo inteligente implementado correctamente, Documento con linea de producción caracterizada Sistema con módulo de verificación de cada variable indicando en comportamiento individual y registro de mediciones que registre tiempo. Protocolo de validación del sistema de seguimiento y monitoreo propuesto desarrollado y probado | AC18: =+IFERROR(P18/L18,0%) -> 0.7774129 | AD18: =+IFERROR((Q18+R18)/L18,0%) -> 0.058195629 | AE18: =IFERROR(Q18/(Q18+R18),0%) -> 0 | AF18: =IFERROR(R18/(Q18+R18),0%) -> 1 | AG18: =+IFERROR((S18+T18)/L18,0%) -> 0.16439148 | AH18: =+IFERROR((U18+V18)/L18,0%) -> 0 | AI18: =+IFERROR((W18+X18)/L18,0%) -> 0 | AJ18: =+IFERROR((Y18+Z18)/L18,0%) -> 0
A19: 2018 | B19: Propuesta de Investigación Convocatoria | C19: No Avalada | D19: 816 | E19: N/A | F19: MinCiencias | G19: Co-ejecutor | H19: 1- FIREFLY ENERGY SAS 2- Universidad de Cundinamarca | I19: N/A | J19: 12 | K19: N/A | L19: =+SUM(P19:Z19) -> 339886600 | M19: 0 | N19: =+P19+Q19+S19+U19+W19+Y19 -> 251886600 | O19: =+R19+T19+V19+X19+Z19 -> 88000000 | P19: 191886600 | Q19: 0 | R19: 48000000 | S19: 60000000 | T19: 0 | U19: 0 | V19: 40000000 | W19: 0 | X19: 0 | Y19: 0 | Z19: 0 | AA19: 1- Análisis de patrones y correlaciones en los reportes de emergencias. 2- Uso de Modelo de inteligencia de máquina y BigData en la predicción de emergencias, y que permita asistir en la coordinación y optimización de equipos de respuesta a emergencias 3- Informe técnico del resultado de análisis de BigData sobre los datos recibidos de reportes de emergencias. 4- Sistema que permita recepción análisis y predicciones por medio de aprendizaje de máquina, encaminado a mejorar la respuesta de equipos de emergencia. 5- Datos estadísticos y anóminos de libre consulta acerca de la geolocalización, frecuencia, clasificación y ocurrencia de reporte de emergencias en la ciudad de Facatativa 6- Diseño de estaciones de monitoreo climático y de otros tipos que se conecten con sistemas de IOT basados en protocolo MQTT | AB19: 1- Publicación Revista Internacional Machine Learning y Big data 2- Ponencia Internacional Machine Learning y Big data aplicado a ciudades inteligentes | AC19: =+IFERROR(P19/L19,0%) -> 0.56456065 | AD19: =+IFERROR((Q19+R19)/L19,0%) -> 0.14122357 | AE19: =IFERROR(Q19/(Q19+R19),0%) -> 0 | AF19: =IFERROR(R19/(Q19+R19),0%) -> 1 | AG19: =+IFERROR((S19+T19)/L19,0%) -> 0.17652947 | AH19: =+IFERROR((U19+V19)/L19,0%) -> 0.11768631 | AI19: =+IFERROR((W19+X19)/L19,0%) -> 0 | AJ19: =+IFERROR((Y19+Z19)/L19,0%) -> 0
A20: 2020 | B20: Propuesta de Investigación Alianza Convenio | C20: Contrato firmado | D20: N/A | E20: N/A | F20: N/A | G20: Aliado | H20: 1- Corporación Universitaria Iberoamericana 2- Fundación Zemillah 3- Saber Colombia Languages Research and Development | I20: N/A | J20: 12 | K20: UDFJC: -Grupo de Investigación Interdisciplinaria en Pedagogía del Lenguaje y las Matemáticas-GIIPLyM. -Grupo de Investigación - Literatura, Educación y Comunicación (LEC) IBERO: - Grupo en Investigación y Escenarios de Educación Pedagógica - GIEEP. | L20: =+SUM(P20:Z20) -> 101651661 | M20: 0 | N20: =+P20+Q20+S20+U20+W20+Y20 -> 7000000 | O20: =+R20+T20+V20+X20+Z20 -> 94651661 | P20: 0 | Q20: 0 | R20: 51500000 | S20: 7000000 | T20: 25783661 | U20: 0 | V20: 8354000 | W20: 0 | X20: 9014000 | Y20: 0 | Z20: 0 | AA20: - Identificación de presencia o no de tópicos de formación relacionados y en lo posible de metodologías y orientaciones metodológicas. - Base conceptual de las categorías. - Formulación de primera versión tipo Artículo con categorías - Talleres para la formación de profesores en experiencia estética en artes y en lenguaje y acogimiento a la diversidad. | AB20: - Un artículo postulado a revista indexada A1, A, B, C y D - Tres prototipos de talleres para formación de estudiantes para profesor. - Un informe de análisis de potencialidades de recursos tecnológicos - Estudiantes vinculados al proyecto como población en formación: - Nueve estudiantes en formación: - Cuatro pasantes de la UDFJC, Facultad de Ciencias y Educación: mediante convocatoria, de los proyectos curriculares Licenciatura Artística (danza), LEBEHLC (literatura y lenguaje), y NEES para diseño, población diversa. - Tres estudiantes asistentes de investigación de la IBERO, convocados por el GIEEP: Ma. de Jesús Blanco: Ibero de los programas de Educación infantil y de Educación especial (uno para población sordas y uno para población ciega y 2 de educación infantil). - Estudiantes de la Facultad Tecnológica, UDFJC vinculados al Módulo innova del CADEP Acacia. - Tres trabajos de grado de estudiantes de pregrado de programas Licenciatura Artística (danza), LEBEHLC (literatura y lenguaje), y NEES de la FCE-UDFJC y estudiantes para profesor en general. | AC20: =+IFERROR(P20/L20,0%) -> 0 | AD20: =+IFERROR((Q20+R20)/L20,0%) -> 0.50663215 | AE20: =IFERROR(Q20/(Q20+R20),0%) -> 0 | AF20: =IFERROR(R20/(Q20+R20),0%) -> 1 | AG20: =+IFERROR((S20+T20)/L20,0%) -> 0.32250984 | AH20: =+IFERROR((U20+V20)/L20,0%) -> 0.082182622 | AI20: =+IFERROR((W20+X20)/L20,0%) -> 0.088675383 | AJ20: =+IFERROR((Y20+Z20)/L20,0%) -> 0
A21: 2018 | B21: Propuesta de Investigación Convocatoria | C21: No Avalada | D21: 816 | E21: N/A | F21: MinCiencias | G21: Co-ejecutor | H21: 1- Praxis IT Colombia LTDA | I21: N/A | J21: 12 | K21: N/A | L21: =+SUM(P21:Z21) -> 599696552 | M21: 0 | N21: =+P21+Q21+S21+U21+W21+Y21 -> 560629662 | O21: =+R21+T21+V21+X21+Z21 -> 39066890 | P21: 400280763 | Q21: 5200000 | R21: 0 | S21: 155148899 | T21: 39066890 | U21: 0 | V21: 0 | W21: 0 | X21: 0 | Y21: 0 | Z21: 0 | AA21: 0 | AB21: Documento o informe de la consultoría en: - Diseño de la Arquitectura - Aseguramiento de la calidad para la implantación - Diseño e implementación de modelos analíticos en la plataforma - Generación de modelos analíticos - Protección de Datos | AC21: =+IFERROR(P21/L21,0%) -> 0.66747218 | AD21: =+IFERROR((Q21+R21)/L21,0%) -> 0.008671052 | AE21: =IFERROR(Q21/(Q21+R21),0%) -> 1 | AF21: =IFERROR(R21/(Q21+R21),0%) -> 0 | AG21: =+IFERROR((S21+T21)/L21,0%) -> 0.32385677 | AH21: =+IFERROR((U21+V21)/L21,0%) -> 0 | AI21: =+IFERROR((W21+X21)/L21,0%) -> 0 | AJ21: =+IFERROR((Y21+Z21)/L21,0%) -> 0
A22: 2021 | B22: Propuesta de Investigación Alianza Convenio | C22: Contrato firmado | D22: N/A | E22: N/A | F22: Universidad Pedagógica Nacional - UPN | G22: Aliado | H22: 1- Universidad Pedagógica Nacional (Colombia) 2- Universidad Alberto Hurtado (Chile) 3- Centro de Investigación y Estudios Avanzados del IPN (CINVESTAV, México 4- Universidade Federal de Santa Catarina (Brasil) | I22: N/A | J22: 42 | K22: UDFJC: - Biología, Enseñanza y Realidades UPN: - Biología, Enseñanza y Realidades CINVESTAV: - Educación en Biología UFSC: - Discursos da Ciência e da Tecnologia na Educação | L22: =+SUM(P22:Z22) -> 698127195 | M22: 0 | N22: =+P22+Q22+S22+U22+W22+Y22 -> 156069919 | O22: =+R22+T22+V22+X22+Z22 -> 542057276 | P22: 0 | Q22: 135004531 | R22: 81038638 | S22: 14065388 | T22: 209570394 | U22: 7000000 | V22: 67994644 | W22: 0 | X22: 91928000 | Y22: 0 | Z22: 91525600 | AA22: FASE I: - De dos a cuatro artículos que presenten los resultados del análisis bibliométrico y del discurso (contenido) - Dos ponencias, presentadas en congresos en enseñanza De las ciencias, formación De profesores y educación en general. - Tres trabajos De grado De pregrado FASE II: - Un artículo de comparación de los resultados obtenidos de los países participantes en relación con las políticas públicas en educación en ciencias y su articulación con la construcción de ciudadanías. - Dos ponencias sobre la relación planteada en esta fase - Simposio FASE III: - Diseño colectivo de ocho propuestas de educación en biología en clave de construcción de ciudadanías - Edición de un libro que sistematice la implementación de las ocho propuestas - Dos trabajos de grado de pregrado - Dos ponencias para la presentación de los resultados de investigación - 5 trabajos de grado de posgrado - Un artículo de investigación | AB22: - De dos a cuatro Artículos de investigación A1, A2, B y C - Un Libro resultado de investigación - Creación de la red Latinoamérica de enseñanza de la biología y construcción de ciudadanías - Organización de dos simposios que permitan reflexionar sobre la relación del proyecto - Participación como ponentes en seis eventos especializados - Dirección de cinco trabajo de grado de maestría en asociación directa al proyecto de investigación de las fases II y III - Dirección de cinco trabajo de grado de pregrado en asociación directa al proyecto de investigación de las fases I y II | AC22: =+IFERROR(P22/L22,0%) -> 0 | AD22: =+IFERROR((Q22+R22)/L22,0%) -> 0.30946104 | AE22: =IFERROR(Q22/(Q22+R22),0%) -> 0.62489609 | AF22: =IFERROR(R22/(Q22+R22),0%) -> 0.37510391 | AG22: =+IFERROR((S22+T22)/L22,0%) -> 0.32033673 | AH22: =+IFERROR((U22+V22)/L22,0%) -> 0.10742261 | AI22: =+IFERROR((W22+X22)/L22,0%) -> 0.13167801 | AJ22: =+IFERROR((Y22+Z22)/L22,0%) -> 0.13110161
A23: 2018 | B23: Propuesta de Investigación Convocatoria | C23: No Avalada | D23: 825 | E23: N/A | F23: MinCiencias | G23: Co-ejecutor | H23: Entidad Ejecutora: 1- Konrad Lorenz Entidad Co-ejecutora: 2- Universidad Católica de Oriente Entidad Sector TIC: 3- Log On Colombia | I23: N/A | J23: 15 | K23: N/A | L23: =+SUM(P23:Z23) -> 1.0101434e+09 | M23: 0 | N23: =+P23+Q23+S23+U23+W23+Y23 -> 698408645 | O23: =+R23+T23+V23+X23+Z23 -> 3.1173471e+08 | P23: 698408645 | Q23: 0 | R23: 131800000 | S23: 0 | T23: 1.3252229e+08 | U23: 0 | V23: 39600000 | W23: 0 | X23: 7812420 | Y23: 0 | Z23: 0 | AA23: * Perfil sociodemográfico y psicográfico de los estudiantes de educación virtual de dos zonas de Antioquia, identificando su perfil tecnológico, su historia de interacción con entornos virtuales y sus competencias de autorregulación * Evidencia, a partir de las actividades de investigación y la metodología descrita, de los componentes pedagógicos necesarios para la implementación del programa. | AB23: * Dos artículos sometidos a revistas de impacto (Q1-Q2). * Informe final sobre el diseño, construcción y validación del programa de intervención pedagógica para la prevención de la deserción y aumento del éxito estudiantil. * Plataforma para la implementación y uso del programa de intervención pedagógica para la prevención de la deserción y aumento del éxito estudiantil. * Informe final sobre las recomendaciones para el uso del programa de intervención pedagógica para la prevención de la deserción y aumento del éxito estudiantil. * Participación en dos eventos científicos. | AC23: =+IFERROR(P23/L23,0%) -> 0.69139557 | AD23: =+IFERROR((Q23+R23)/L23,0%) -> 0.13047653 | AE23: =IFERROR(Q23/(Q23+R23),0%) -> 0 | AF23: =IFERROR(R23/(Q23+R23),0%) -> 1 | AG23: =+IFERROR((S23+T23)/L23,0%) -> 0.13119157 | AH23: =+IFERROR((U23+V23)/L23,0%) -> 0.039202357 | AI23: =+IFERROR((W23+X23)/L23,0%) -> 0.0077339716 | AJ23: =+IFERROR((Y23+Z23)/L23,0%) -> 0
A24: 2021 | B24: Propuesta de Investigación Alianza Convenio | C24: Contrato firmado | D24: N/A | E24: N/A | F24: EAN - ICC | G24: Aliado | H24: 1- Universidad EAN 2- Instituto Caro y Cuervo | I24: N/A | J24: 15 | K24: UDFJC: - ESTUPOLI EAN: - Lingüística aplicada y comunicación organizacional ICC: - Linguistica | L24: =+SUM(P24:Z24) -> 49779000 | M24: 0 | N24: =+P24+Q24+S24+U24+W24+Y24 -> 0 | O24: =+R24+T24+V24+X24+Z24 -> 49779000 | P24: 0 | Q24: 0 | R24: 18456000 | S24: 0 | T24: 7640000 | U24: 0 | V24: 23683000 | W24: 0 | X24: 0 | Y24: 0 | Z24: 0 | AA24: - 10 participantes, profesores entre los que están 5 de inglés y 5 de español - El protocolo de las entrevistas - Grabaciones de las entrevistas - Transcripción y codificación de transcripción de las entrevistas - Una recolección de propuestas metodológicas sistematizadas por temáticas, objetivos y metodologías - Instrumento en forma de matriz para análisis de propuestas - Propuestas insertadas en las matrices diseñadas - Informe de análisis | AB24: 0 | AC24: =+IFERROR(P24/L24,0%) -> 0 | AD24: =+IFERROR((Q24+R24)/L24,0%) -> 0.37075875 | AE24: =IFERROR(Q24/(Q24+R24),0%) -> 0 | AF24: =IFERROR(R24/(Q24+R24),0%) -> 1 | AG24: =+IFERROR((S24+T24)/L24,0%) -> 0.15347837 | AH24: =+IFERROR((U24+V24)/L24,0%) -> 0.47576287 | AI24: =+IFERROR((W24+X24)/L24,0%) -> 0 | AJ24: =+IFERROR((Y24+Z24)/L24,0%) -> 0
A25: 2018 | B25: Propuesta de Investigación Convocatoria | C25: No Avalada | D25: Convocatoria de investigaciones 2018 para presentar proyectos de CT+I en temáticas relacionadas con la planeación, gestión eficiente, atribución, vigilancia y control del espectro radioeléctrico en Colombia | E25: N/A | F25: Agencia Nacional del Espectro - ANE | G25: Ejecutor | H25: N/A | I25: N/A | J25: 11 | K25: N/A | L25: =+SUM(P25:Z25) -> 363820662 | M25: 0 | N25: =+P25+Q25+S25+U25+W25+Y25 -> 248389600 | O25: =+R25+T25+V25+X25+Z25 -> 115431062 | P25: 248389600 | Q25: 0 | R25: 115431062 | S25: 0 | T25: 0 | U25: 0 | V25: 0 | W25: 0 | X25: 0 | Y25: 0 | Z25: 0 | AA25: 0 | AB25: 1- El resultado esperado de esta fase del proyecto es un informe de los métodos de planificación utilizados actualmente por los diferentes operadores de televisión, así mismo una clasificación de dichos modelos eleccionando los índices de gestión de recursos en el espectro radioeléctrico, para así buscar una comparación pertinente para realizar de forma adecuada y eficiente la puesta en funcionamiento de la metodología que es el objetivo de este proyecto. 2- El resultado esperado de esta fase del proyecto se compone de un informe que unifique los criterios y procedimientos necesarios en la planificación de redes de televisión digital terrestre, incluyendo una sección de pruebas de campo y/o laboratorio, se seleccionaran los lugares más representativos de la región rural de Cundinamarca para realizar las mediciones. Aquí se busca tener un componente comparativo de los comportamientos de los modelos en entornos rurales. La redacción de un documento de socialización para estudiantes de la Facultad de Ingeniería de la Universidad Distrital permitirá mostrar los avances logrados en esta fase, de igual forma la presentación de los mismos en un evento nacional/internacional en el formato ponencia o poster. 3- El resultado esperado de esta fase del proyecto se compone de un documento de análisis de todo lo relacionado con la gestión del modelo para la parametrización de coberturas y asignación eficiente del espectro radioeléctrico, a través de análisis pertinentes y verificación de campo para generar la metodología propuesta. Así mismo de los análisis de coberturas, interferencias, eficiencia de frecuencias en entornos rurales y su respectiva validación de campo. En esta fase se preparará un documento tipo artículo para presentar en revista internacional indexada. 4- En esta etapa se recopilará la información obtenida con las fases anteriores. Esta documentación tiene el objeto de describir claramente la metodología para la planificación de redes de televisión digital terrestre en el entorno rural de Cundinamarca, así mismo la integración de los procesos que se seleccionaron para posteriores trabajos y/o desarrollos. Se postulará el artículo redactado en la fase anterior en una revista internacional indexada. | AC25: =+IFERROR(P25/L25,0%) -> 0.68272538 | AD25: =+IFERROR((Q25+R25)/L25,0%) -> 0.31727462 | AE25: =IFERROR(Q25/(Q25+R25),0%) -> 0 | AF25: =IFERROR(R25/(Q25+R25),0%) -> 1 | AG25: =+IFERROR((S25+T25)/L25,0%) -> 0 | AH25: =+IFERROR((U25+V25)/L25,0%) -> 0 | AI25: =+IFERROR((W25+X25)/L25,0%) -> 0 | AJ25: =+IFERROR((Y25+Z25)/L25,0%) -> 0
A26: 2018 | B26: Propuesta de Investigación Convocatoria | C26: No Avalada | D26: 828 | E26: N/A | F26: MinCiencias | G26: Co-ejecutor | H26: 1- Ejecutor:TECSOL 2- Aliado Institucional: Alcaldía de Guacheta | I26: N/A | J26: 18 | K26: N/A | L26: =+SUM(P26:Z26) -> 417331506 | M26: 0 | N26: =+P26+Q26+S26+U26+W26+Y26 -> 287770013 | O26: =+R26+T26+V26+X26+Z26 -> 129561493 | P26: 287770013 | Q26: 0 | R26: 40162098 | S26: 0 | T26: 89399395 | U26: 0 | V26: 0 | W26: 0 | X26: 0 | Y26: 0 | Z26: 0 | AA26: * Implementar cuatro sistemas generadores de biogás y bioabono cuyo funcionamiento permite dar uso a los residuos orgánicos resultantes de los procesos productivos agropecuarios y domiciliarios con el fin de generar biogás y bioabono para su reutilización en el proceso productivo, como acercamiento a un ciclo de economía circular. * Agremiar inicialmente a veinte hogares de siete veredas del municipio de Guachetá para capacitarlos acerca de diversos aspectos que rodean la valorización energética de sus residuos orgánicos. * Desarrollar una aplicación móvil para la recolección de datos obtenidos durante los procesos de digestión anaerobia, entre otras experiencias y resultados que se puedan dar de este proyecto, con el fin de garantizar la construcción colectiva del conocimiento. * Generar una caracterización de la zona geográfica que sirva para futuras investigaciones en el área de los biodigestores. * Estimar la reducción de uso de recursos energéticos en los procesos productivos al usar el producto de los biodigestores, además de materia orgánica que deja de ser arrojada a los vertederos. | AB26: 1. Productos resultados de actividades de generación de nuevo conocimiento. - 1 Artículo de investigación 2. Productos resultados de actividades de desarrollo tecnológico e innovación. - 1 Producto tecnológico certificado o validado: c.Software (aplicación móvil). 3. Productos resultados de actividades de apropiación social del conocimiento. - Participación ciudadana en CTeI: b. Espacios de participación ciudadana en CTeI. - Circulación de conocimiento especializado: a. Participaciones u organizaciones de eventos científicos, tecnológicos y de innovación (congresos, seminarios, foros, conversatorios, talleres, entre otros). 4. Productos de actividades relacionadas con la formación de recurso humano para CTeI. - Estudiante de 1 pregrado y 1 maestría: b. Vinculación de estudiantes de pregrado y maestría. | AC26: =+IFERROR(P26/L26,0%) -> 0.68954778 | AD26: =+IFERROR((Q26+R26)/L26,0%) -> 0.09623548 | AE26: =IFERROR(Q26/(Q26+R26),0%) -> 0 | AF26: =IFERROR(R26/(Q26+R26),0%) -> 1 | AG26: =+IFERROR((S26+T26)/L26,0%) -> 0.21421674 | AH26: =+IFERROR((U26+V26)/L26,0%) -> 0 | AI26: =+IFERROR((W26+X26)/L26,0%) -> 0 | AJ26: =+IFERROR((Y26+Z26)/L26,0%) -> 0
A27: 2018 | B27: Propuesta de Investigación Convocatoria | C27: No Avalada | D27: 829 | E27: N/A | F27: MinCiencias | G27: Co-ejecutor | H27: 1- Ejecutor:TECSOL 2- Aliado Institucional: Alcaldía de Guacheta | I27: N/A | J27: 18 | K27: N/A | L27: =+SUM(P27:Z27) -> 417331506 | M27: 0 | N27: =+P27+Q27+S27+U27+W27+Y27 -> 287770013 | O27: =+R27+T27+V27+X27+Z27 -> 129561493 | P27: 287770013 | Q27: 0 | R27: 40162098 | S27: 0 | T27: 89399395 | U27: 0 | V27: 0 | W27: 0 | X27: 0 | Y27: 0 | Z27: 0 | AA27: * Implementar cuatro sistemas generadores de biogás y bioabono cuyo funcionamiento permite dar uso a los residuos orgánicos resultantes de los procesos productivos agropecuarios y domiciliarios con el fin de generar biogás y bioabono para su reutilización en el proceso productivo, como acercamiento a un ciclo de economía circular. * Agremiar inicialmente a veinte hogares de siete veredas del municipio de Guachetá para capacitarlos acerca de diversos aspectos que rodean la valorización energética de sus residuos orgánicos. * Desarrollar una aplicación móvil para la recolección de datos obtenidos durante los procesos de digestión anaerobia, entre otras experiencias y resultados que se puedan dar de este proyecto, con el fin de garantizar la construcción colectiva del conocimiento. * Generar una caracterización de la zona geográfica que sirva para futuras investigaciones en el área de los biodigestores. * Estimar la reducción de uso de recursos energéticos en los procesos productivos al usar el producto de los biodigestores, además de materia orgánica que deja de ser arrojada a los vertederos. | AB27: 1. Productos resultados de actividades de generación de nuevo conocimiento. - 1 Artículo de investigación 2. Productos resultados de actividades de desarrollo tecnológico e innovación. - 1 Producto tecnológico certificado o validado: c.Software (aplicación móvil). 3. Productos resultados de actividades de apropiación social del conocimiento. - Participación ciudadana en CTeI: b. Espacios de participación ciudadana en CTeI. - Circulación de conocimiento especializado: a. Participaciones u organizaciones de eventos científicos, tecnológicos y de innovación (congresos, seminarios, foros, conversatorios, talleres, entre otros). 4. Productos de actividades relacionadas con la formación de recurso humano para CTeI. - Estudiante de 1 pregrado y 1 maestría: b. Vinculación de estudiantes de pregrado y maestría. | AC27: =+IFERROR(P27/L27,0%) -> 0.68954778 | AD27: =+IFERROR((Q27+R27)/L27,0%) -> 0.09623548 | AE27: =IFERROR(Q27/(Q27+R27),0%) -> 0 | AF27: =IFERROR(R27/(Q27+R27),0%) -> 1 | AG27: =+IFERROR((S27+T27)/L27,0%) -> 0.21421674 | AH27: =+IFERROR((U27+V27)/L27,0%) -> 0 | AI27: =+IFERROR((W27+X27)/L27,0%) -> 0 | AJ27: =+IFERROR((Y27+Z27)/L27,0%) -> 0
A28: 2018 | B28: Propuesta de Investigación Convocatoria | C28: No Avalada | D28: 829 | E28: N/A | F28: MinCiencias | G28: Co-ejecutor | H28: 1- Ejecutor: Corporación Universitaria Minuto de Dios 2- Aliado: Corporación Centauro Bacata | I28: N/A | J28: 18 | K28: N/A | L28: =+SUM(P28:Z28) -> 509627362 | M28: 0 | N28: =+P28+Q28+S28+U28+W28+Y28 -> 381426362 | O28: =+R28+T28+V28+X28+Z28 -> 128201000 | P28: 349676362 | Q28: 31750000 | R28: 45100000 | S28: 0 | T28: 83101000 | U28: 0 | V28: 0 | W28: 0 | X28: 0 | Y28: 0 | Z28: 0 | AA28: Se espera obtener los siguientes resultados: 1- Actividades de Nuevo conocimiento: Libro, Un articulo. 2- Actividades Desarrollo tecnológico e innovación: Mapa de la cobertera vegetal, Guía de cuidado y uso de especies vegetales. 3- Actividades de Apropiación social del conocimiento: Participación ciudadana en productos CTel, Alianza con centro dedicado a la apropiación social del conocimiento. 4- Actividades de formación del recurso humano: Formación de 4 estudiantes de pregrado, Formación de dos estudiantes de maestría. | AB28: * Cartilla guia para identificar, cuidadar y aprovechar las especies vegetales presentes en la zona. * Libro Publicación con los resultados obtenidos y la metodología desarrollada * Mapa de la cobertera vegetal del área investigada * Alianza con los centros educativos de los municipios de Choachí, Ubaque y Fómeque * Tesis de grado de maestría, trabajo de campo e instruirán a los estudiantes. * Vinculación estudiantes de pregrado Apoyarán todo el proceso de la investigación y trabajarán en campo e instruirán a los estudiantes * Formación estudiantes de pregrado | AC28: =+IFERROR(P28/L28,0%) -> 0.68614126 | AD28: =+IFERROR((Q28+R28)/L28,0%) -> 0.15079646 | AE28: =IFERROR(Q28/(Q28+R28),0%) -> 0.41314249 | AF28: =IFERROR(R28/(Q28+R28),0%) -> 0.58685751 | AG28: =+IFERROR((S28+T28)/L28,0%) -> 0.16306228 | AH28: =+IFERROR((U28+V28)/L28,0%) -> 0 | AI28: =+IFERROR((W28+X28)/L28,0%) -> 0 | AJ28: =+IFERROR((Y28+Z28)/L28,0%) -> 0
